package com.sergax.functional.chapter_7.mapping_results_and_recovering_from_exceptions;

import java.util.NoSuchElementException;
import java.util.Optional;
import java.util.function.Predicate;
import java.util.function.Supplier;

/**
 * @author : sergax
 * @date : 04.06.22
 */
public interface Try<T> {
    /**
     * Executes the given operation and returns the result wrapped in a Success or Failure
     */
    static <T> Try<T> of(ThrowableOperation<T> operation) {
        // take it from the previous step
        try {
            return new Success<>(operation.execute());
        } catch (Throwable e) {
            return new Failure<>(e);
        }
    }

    /**
     * Returns true if the original operation succeeded, otherwise returns false
     */
    boolean isSuccess();

    /**
     * Returns the resulting value if this is a Success, otherwise throws the original exception
     */
    T get() throws Throwable;

    /**
     * Returns the resulting value if this is a Success,
     * otherwise throws the original exception wrapped in a RuntimeException
     *
     * @throws RuntimeException that wraps the original exception
     */
    T getUnchecked();

    /**
     * Converts this to a non-empty Optional that wraps the resulting value if this is Success,
     * otherwise returns an empty Optional
     */
    Optional<T> toOptional();

    /**
     * Returns the given default value if this is a Failure,
     * otherwise returns the resulting value
     */
    T getOrElse(T defaultValue);

    /**
     * Returns the resulting value if it is a Success,
     * otherwise returns the result produced by the given supplier
     */
    T getOrElseSupply(Supplier<? extends T> supplier);

    /**
     * Returns the resulting value if this is a Success,
     * otherwise throws an exception produced by the exception supplier
     *
     * @throws Throwable produced by the exception supplier
     */
    <X extends Throwable> T getOrElseThrow(Supplier<? extends X> exceptionSupplier) throws X;

    /**
     * Applies the given action to the resulting value if it is a Success, otherwise does nothing
     *
     * @return the current Try object
     * @throws E if the action throws an exception
     */
    <E extends Throwable> Try<T> onSuccess(ThrowableConsumer<T, E> action) throws E;

    /**
     * Applies the given action to the exception if it is a Failure, otherwise does nothing
     *
     * @return the current Try object
     * @throws E if the action throws an exception
     */
    <E extends Throwable> Try<T> onFailure(ThrowableConsumer<Throwable, E> action) throws E;

    /**
     * Converts this Success into a Failure (which holds NoSuchElementException)
     * if it is a Success and the predicate doesn't match for the value,
     * otherwise returns this Try (Success or Failure)
     */
    Try<T> filter(Predicate<T> predicate);

    /**
     * Applies the given function to the resulting value if is a Success, otherwise returns this Failure.
     * If that function fails a Failure is returned
     */
    <U> Try<U> map(ThrowableFunction<? super T, ? extends U> function);

    /**
     * Applies the given function to the resulting value if is a Success, otherwise returns this Failure.
     * If that function fails a Failure is returned.
     * <p>
     * This method is similar to {@link Try#map}, but the mapping function already returns a Try.
     * Being invoked this method doesn't wrap the result of this function within a nested optional
     */
    <U> Try<U> flatMap(ThrowableFunction<? super T, Try<U>> function);

    /**
     * Applies the given function to recover from the throwable if it is a Failure,
     * otherwise returns this Success.
     *
     * @return a new Try in the case of failure, or the current Success
     */
    Try<T> recover(ThrowableFunction<? super Throwable, T> function);

    /**
     * Applies the given function to recover from the throwable if it is a Failure,
     * otherwise returns this Success.
     * <p>
     * This method is similar to {@link Try#recover}, but the recovering function already returns a Try.
     * Being invoked this method doesn't wrap the result of this function within a nested optional
     *
     * @return a new Try provided by the given function in the case of failure, or the current Success
     */
    Try<T> recoverWith(ThrowableFunction<? super Throwable, Try<T>> function);
}
